Workbook

Sheet Trend

Sheet Equipment Analysis
A1: Underground Construction
A2: 45961
A7: UCCo/UEC
C8: Equipment Costs | Q8: Equipment Costs per direct manhour
C9: January | D9: February | E9: March | F9: April | G9: May | H9: June | I9: July | J9: August | K9: September | L9: October | M9: November | N9: December | O9: YTD | Q9: January | R9: February | S9: March | T9: April | U9: May | V9: June | W9: July | X9: August | Y9: September | Z9: October | AA9: November | AB9: Dec | AC9: YTD
A10: Labor/Burden | B10: 2_Labor/Burden | C10: 590505.76 | D10: 561250.61 | E10: 523561.62 | F10: 492297.23 | G10: 572341.77 | H10: 512847.69 | I10: =SUMIFS(UCCo_IMC!K$3:K$35,UCCo_IMC!$C$3:$C$35,'Equipment Analysis'!$B10,UCCo_IMC!$D$3:$D$35,341) -> 740150.95 | J10: =SUMIFS(UCCo_IMC!L$3:L$35,UCCo_IMC!$C$3:$C$35,'Equipment Analysis'!$B10,UCCo_IMC!$D$3:$D$35,341) -> 570230.96 | K10: =SUMIFS(UCCo_IMC!M$3:M$35,UCCo_IMC!$C$3:$C$35,'Equipment Analysis'!$B10,UCCo_IMC!$D$3:$D$35,341) -> 653440.65 | L10: =SUMIFS(UCCo_IMC!N$3:N$35,UCCo_IMC!$C$3:$C$35,'Equipment Analysis'!$B10,UCCo_IMC!$D$3:$D$35,341) -> 675553.09 | M10: =SUMIFS(UCCo_IMC!O$3:O$35,UCCo_IMC!$C$3:$C$35,'Equipment Analysis'!$B10,UCCo_IMC!$D$3:$D$35,341) -> 0 | N10: =SUMIFS(UCCo_IMC!P$3:P$35,UCCo_IMC!$C$3:$C$35,'Equipment Analysis'!$B10,UCCo_IMC!$D$3:$D$35,341) -> 0 | O10: =SUM(C10:N10) -> 5892180.3 | Q10: =+C10/(C$50+C$52+C$53) -> 7.6024096 | R10: =IFERROR(D10/(D$50+D$52+D$53),0) -> 9.6842483 | S10: =IFERROR(E10/(E$50+E$52+E$53),0) -> 8.9191656 | T10: =IFERROR(F10/(F$50+F$52+F$53),0) -> 6.0369783 | U10: =IFERROR(G10/(G$50+G$52+G$53),0) -> 7.5633941 | V10: =IFERROR(H10/(H$50+H$52+H$53),0) -> 7.5825694 | W10: =IFERROR(I10/(I$50+I$52+I$53),0) -> 6.2141104 | X10: =IFERROR(J10/(J$50+J$52+J$53),0) -> 5.9328143 | Y10: =IFERROR(K10/(K$50+K$52+K$53),0) -> 6.0768074 | ... AB10: =IFERROR(N10/(N$50+N$52+N$53),0) -> 0 | AC10: =+O10/(O$50+O$52+O$53) -> 6.8882285
A11: EQ Rentals | B11: 3_EQ Rentals | C11: 293422.21 | D11: 231941.64 | E11: 49706.42 | F11: 340243.92 | G11: 406620.5 | H11: -9864.56 | I11: =SUMIFS(UCCo_IMC!K$3:K$35,UCCo_IMC!$C$3:$C$35,'Equipment Analysis'!$B11,UCCo_IMC!$D$3:$D$35,341) -> 739131.43 | J11: =SUMIFS(UCCo_IMC!L$3:L$35,UCCo_IMC!$C$3:$C$35,'Equipment Analysis'!$B11,UCCo_IMC!$D$3:$D$35,341) -> 251897.61 | K11: =SUMIFS(UCCo_IMC!M$3:M$35,UCCo_IMC!$C$3:$C$35,'Equipment Analysis'!$B11,UCCo_IMC!$D$3:$D$35,341) -> 435893.39 | L11: =SUMIFS(UCCo_IMC!N$3:N$35,UCCo_IMC!$C$3:$C$35,'Equipment Analysis'!$B11,UCCo_IMC!$D$3:$D$35,341) -> 344975.35 | M11: =SUMIFS(UCCo_IMC!O$3:O$35,UCCo_IMC!$C$3:$C$35,'Equipment Analysis'!$B11,UCCo_IMC!$D$3:$D$35,341) -> 0 | N11: =SUMIFS(UCCo_IMC!P$3:P$35,UCCo_IMC!$C$3:$C$35,'Equipment Analysis'!$B11,UCCo_IMC!$D$3:$D$35,341) -> 0 | O11: =SUM(C11:N11) -> 3083967.9 | Q11: =+C11/(C$50+C$52+C$53) -> 3.777636 | R11: =IFERROR(D11/(D$50+D$52+D$53),0) -> 4.0020989 | S11: =IFERROR(E11/(E$50+E$52+E$53),0) -> 0.84677672 | T11: =IFERROR(F11/(F$50+F$52+F$53),0) -> 4.1723679 | U11: =IFERROR(G11/(G$50+G$52+G$53),0) -> 5.3734171 | V11: =IFERROR(H11/(H$50+H$52+H$53),0) -> -0.14584976 | W11: =IFERROR(I11/(I$50+I$52+I$53),0) -> 6.2055508 | X11: =IFERROR(J11/(J$50+J$52+J$53),0) -> 2.6208008 | Y11: =IFERROR(K11/(K$50+K$52+K$53),0) -> 4.0536814 | ... AB11: =IFERROR(N11/(N$50+N$52+N$53),0) -> 0 | AC11: =+O11/(O$50+O$52+O$53) -> 3.6052996
A12: EQ Leasing | B12: 4_EQ Leasing | C12: 392435.02 | D12: 403947.87 | E12: 407412.74 | F12: 388972.38 | G12: 395347.45 | H12: 391476.87 | I12: =SUMIFS(UCCo_IMC!K$3:K$35,UCCo_IMC!$C$3:$C$35,'Equipment Analysis'!$B12,UCCo_IMC!$D$3:$D$35,341) -> 394134.84 | J12: =SUMIFS(UCCo_IMC!L$3:L$35,UCCo_IMC!$C$3:$C$35,'Equipment Analysis'!$B12,UCCo_IMC!$D$3:$D$35,341) -> 444552.79 | K12: =SUMIFS(UCCo_IMC!M$3:M$35,UCCo_IMC!$C$3:$C$35,'Equipment Analysis'!$B12,UCCo_IMC!$D$3:$D$35,341) -> 392068.76 | L12: =SUMIFS(UCCo_IMC!N$3:N$35,UCCo_IMC!$C$3:$C$35,'Equipment Analysis'!$B12,UCCo_IMC!$D$3:$D$35,341) -> 411163.05 | M12: =SUMIFS(UCCo_IMC!O$3:O$35,UCCo_IMC!$C$3:$C$35,'Equipment Analysis'!$B12,UCCo_IMC!$D$3:$D$35,341) -> 0 | N12: =SUMIFS(UCCo_IMC!P$3:P$35,UCCo_IMC!$C$3:$C$35,'Equipment Analysis'!$B12,UCCo_IMC!$D$3:$D$35,341) -> 0 | O12: =SUM(C12:N12) -> 4021511.8 | Q12: =+C12/(C$50+C$52+C$53) -> 5.0523669 | R12: =IFERROR(D12/(D$50+D$52+D$53),0) -> 6.9700262 | S12: =IFERROR(E12/(E$50+E$52+E$53),0) -> 6.9405043 | T12: =IFERROR(F12/(F$50+F$52+F$53),0) -> 4.7699188 | U12: =IFERROR(G12/(G$50+G$52+G$53),0) -> 5.2244458 | V12: =IFERROR(H12/(H$50+H$52+H$53),0) -> 5.7880743 | W12: =IFERROR(I12/(I$50+I$52+I$53),0) -> 3.3090512 | X12: =IFERROR(J12/(J$50+J$52+J$53),0) -> 4.6252296 | Y12: =IFERROR(K12/(K$50+K$52+K$53),0) -> 3.6461251 | ... AB12: =IFERROR(N12/(N$50+N$52+N$53),0) -> 0 | AC12: =+O12/(O$50+O$52+O$53) -> 4.7013313
A13: Depreciation | B13: 5_Depreciation | C13: 163566.12 | D13: 161170.72 | E13: 154781.97 | F13: 153255.73 | G13: 148043.93 | H13: 145367.08 | I13: =SUMIFS(UCCo_IMC!K$3:K$35,UCCo_IMC!$C$3:$C$35,'Equipment Analysis'!$B13,UCCo_IMC!$D$3:$D$35,341) -> 144944.34 | J13: =SUMIFS(UCCo_IMC!L$3:L$35,UCCo_IMC!$C$3:$C$35,'Equipment Analysis'!$B13,UCCo_IMC!$D$3:$D$35,341) -> 142161.16 | K13: =SUMIFS(UCCo_IMC!M$3:M$35,UCCo_IMC!$C$3:$C$35,'Equipment Analysis'!$B13,UCCo_IMC!$D$3:$D$35,341) -> 149636.58 | L13: =SUMIFS(UCCo_IMC!N$3:N$35,UCCo_IMC!$C$3:$C$35,'Equipment Analysis'!$B13,UCCo_IMC!$D$3:$D$35,341) -> 145525.25 | M13: =SUMIFS(UCCo_IMC!O$3:O$35,UCCo_IMC!$C$3:$C$35,'Equipment Analysis'!$B13,UCCo_IMC!$D$3:$D$35,341) -> 0 | N13: =SUMIFS(UCCo_IMC!P$3:P$35,UCCo_IMC!$C$3:$C$35,'Equipment Analysis'!$B13,UCCo_IMC!$D$3:$D$35,341) -> 0 | O13: =SUM(C13:N13) -> 1508452.9 | Q13: =+C13/(C$50+C$52+C$53) -> 2.1058163 | R13: =IFERROR(D13/(D$50+D$52+D$53),0) -> 2.7809632 | S13: =IFERROR(E13/(E$50+E$52+E$53),0) -> 2.6367976 | T13: =IFERROR(F13/(F$50+F$52+F$53),0) -> 1.8793555 | U13: =IFERROR(G13/(G$50+G$52+G$53),0) -> 1.956374 | V13: =IFERROR(H13/(H$50+H$52+H$53),0) -> 2.1492853 | W13: =IFERROR(I13/(I$50+I$52+I$53),0) -> 1.2169141 | X13: =IFERROR(J13/(J$50+J$52+J$53),0) -> 1.4790775 | Y13: =IFERROR(K13/(K$50+K$52+K$53),0) -> 1.3915765 | ... AB13: =IFERROR(N13/(N$50+N$52+N$53),0) -> 0 | AC13: =+O13/(O$50+O$52+O$53) -> 1.7634505
A14: Outside Materials | B14: 6_Outside Materials | C14: 178220.96 | D14: 175529.79 | E14: 201766.26 | F14: 244800.07 | G14: 267759.36 | H14: 464535.3 | I14: =SUMIFS(UCCo_IMC!K$3:K$35,UCCo_IMC!$C$3:$C$35,'Equipment Analysis'!$B14,UCCo_IMC!$D$3:$D$35,341) -> 152083.11 | J14: =SUMIFS(UCCo_IMC!L$3:L$35,UCCo_IMC!$C$3:$C$35,'Equipment Analysis'!$B14,UCCo_IMC!$D$3:$D$35,341) -> 276135.89 | K14: =SUMIFS(UCCo_IMC!M$3:M$35,UCCo_IMC!$C$3:$C$35,'Equipment Analysis'!$B14,UCCo_IMC!$D$3:$D$35,341) -> 102598.69 | L14: =SUMIFS(UCCo_IMC!N$3:N$35,UCCo_IMC!$C$3:$C$35,'Equipment Analysis'!$B14,UCCo_IMC!$D$3:$D$35,341) -> 479935.34 | M14: =SUMIFS(UCCo_IMC!O$3:O$35,UCCo_IMC!$C$3:$C$35,'Equipment Analysis'!$B14,UCCo_IMC!$D$3:$D$35,341) -> 0 | N14: =SUMIFS(UCCo_IMC!P$3:P$35,UCCo_IMC!$C$3:$C$35,'Equipment Analysis'!$B14,UCCo_IMC!$D$3:$D$35,341) -> 0 | O14: =SUM(C14:N14) -> 2543364.8 | Q14: =+C14/(C$50+C$52+C$53) -> 2.2944886 | R14: =IFERROR(D14/(D$50+D$52+D$53),0) -> 3.0287256 | S14: =IFERROR(E14/(E$50+E$52+E$53),0) -> 3.4372013 | T14: =IFERROR(F14/(F$50+F$52+F$53),0) -> 3.0019521 | U14: =IFERROR(G14/(G$50+G$52+G$53),0) -> 3.538392 | V14: =IFERROR(H14/(H$50+H$52+H$53),0) -> 6.8682598 | W14: =IFERROR(I14/(I$50+I$52+I$53),0) -> 1.2768493 | X14: =IFERROR(J14/(J$50+J$52+J$53),0) -> 2.8729814 | Y14: =IFERROR(K14/(K$50+K$52+K$53),0) -> 0.95413788 | ... AB14: =IFERROR(N14/(N$50+N$52+N$53),0) -> 0 | AC14: =+O14/(O$50+O$52+O$53) -> 2.9733098
A15: 3rd Party Labor | B15: 6.1_3rd Party Labor | C15: 27833.24 | D15: 3174.73 | E15: 7854.96 | F15: 42630.54 | G15: 26580.54 | H15: 14537 | I15: =SUMIFS(UCCo_IMC!K$3:K$35,UCCo_IMC!$C$3:$C$35,'Equipment Analysis'!$B15,UCCo_IMC!$D$3:$D$35,341) -> 302633.14 | J15: =SUMIFS(UCCo_IMC!L$3:L$35,UCCo_IMC!$C$3:$C$35,'Equipment Analysis'!$B15,UCCo_IMC!$D$3:$D$35,341) -> 94383.24 | K15: =SUMIFS(UCCo_IMC!M$3:M$35,UCCo_IMC!$C$3:$C$35,'Equipment Analysis'!$B15,UCCo_IMC!$D$3:$D$35,341) -> 331233.84 | L15: =SUMIFS(UCCo_IMC!N$3:N$35,UCCo_IMC!$C$3:$C$35,'Equipment Analysis'!$B15,UCCo_IMC!$D$3:$D$35,341) -> 59879.37 | M15: =SUMIFS(UCCo_IMC!O$3:O$35,UCCo_IMC!$C$3:$C$35,'Equipment Analysis'!$B15,UCCo_IMC!$D$3:$D$35,341) -> 0 | N15: =SUMIFS(UCCo_IMC!P$3:P$35,UCCo_IMC!$C$3:$C$35,'Equipment Analysis'!$B15,UCCo_IMC!$D$3:$D$35,341) -> 0 | O15: =SUM(C15:N15) -> 910740.6 | Q15: =+C15/(C$50+C$52+C$53) -> 0.35833637 | R15: =IFERROR(D15/(D$50+D$52+D$53),0) -> 0.054779225 | S15: =IFERROR(E15/(E$50+E$52+E$53),0) -> 0.13381365 | T15: =IFERROR(F15/(F$50+F$52+F$53),0) -> 0.52277289 | U15: =IFERROR(G15/(G$50+G$52+G$53),0) -> 0.35125708 | V15: =IFERROR(H15/(H$50+H$52+H$53),0) -> 0.21493284 | W15: =IFERROR(I15/(I$50+I$52+I$53),0) -> 2.5408273 | X15: =IFERROR(J15/(J$50+J$52+J$53),0) -> 0.98198497 | Y15: =IFERROR(K15/(K$50+K$52+K$53),0) -> 3.0803781 | ... AB15: =IFERROR(N15/(N$50+N$52+N$53),0) -> 0 | AC15: =+O15/(O$50+O$52+O$53) -> 1.0646974
A16: Inventory Purchase | B16: 6.2_Inventory Purchase | C16: 68681.6 | D16: 73636.3 | E16: 115487.02 | F16: 263793.12 | G16: 178845.52 | H16: 186614.69 | I16: =SUMIFS(UCCo_IMC!K$3:K$35,UCCo_IMC!$C$3:$C$35,'Equipment Analysis'!$B16,UCCo_IMC!$D$3:$D$35,341) -> -466840.38 | J16: =SUMIFS(UCCo_IMC!L$3:L$35,UCCo_IMC!$C$3:$C$35,'Equipment Analysis'!$B16,UCCo_IMC!$D$3:$D$35,341) -> -120205.35 | K16: =SUMIFS(UCCo_IMC!M$3:M$35,UCCo_IMC!$C$3:$C$35,'Equipment Analysis'!$B16,UCCo_IMC!$D$3:$D$35,341) -> -110116.2 | L16: =SUMIFS(UCCo_IMC!N$3:N$35,UCCo_IMC!$C$3:$C$35,'Equipment Analysis'!$B16,UCCo_IMC!$D$3:$D$35,341) -> -128248.1 | M16: =SUMIFS(UCCo_IMC!O$3:O$35,UCCo_IMC!$C$3:$C$35,'Equipment Analysis'!$B16,UCCo_IMC!$D$3:$D$35,341) -> 0 | N16: =SUMIFS(UCCo_IMC!P$3:P$35,UCCo_IMC!$C$3:$C$35,'Equipment Analysis'!$B16,UCCo_IMC!$D$3:$D$35,341) -> 0 | O16: =SUM(C16:N16) -> 61648.22 | Q16: =+C16/(C$50+C$52+C$53) -> 0.88423465 | R16: =IFERROR(D16/(D$50+D$52+D$53),0) -> 1.2705772 | S16: =IFERROR(E16/(E$50+E$52+E$53),0) -> 1.9673861 | T16: =IFERROR(F16/(F$50+F$52+F$53),0) -> 3.2348615 | U16: =IFERROR(G16/(G$50+G$52+G$53),0) -> 2.3634115 | V16: =IFERROR(H16/(H$50+H$52+H$53),0) -> 2.7591405 | W16: =IFERROR(I16/(I$50+I$52+I$53),0) -> -3.9194676 | X16: =IFERROR(J16/(J$50+J$52+J$53),0) -> -1.2506442 | Y16: =IFERROR(K16/(K$50+K$52+K$53),0) -> -1.0240485 | ... AB16: =IFERROR(N16/(N$50+N$52+N$53),0) -> 0 | AC16: =+O16/(O$50+O$52+O$53) -> 0.072069591
A17: Inventory Sales | B17: 6.3_ Inventory Sales | C17: -31565.05 | D17: -39067.5 | E17: -10053.11 | F17: -305997.29 | G17: -135336.35 | H17: -155908.15 | I17: =SUMIFS(UCCo_IMC!K$3:K$35,UCCo_IMC!$C$3:$C$35,'Equipment Analysis'!$B17,UCCo_IMC!$D$3:$D$35,341) -> 0 | J17: =SUMIFS(UCCo_IMC!L$3:L$35,UCCo_IMC!$C$3:$C$35,'Equipment Analysis'!$B17,UCCo_IMC!$D$3:$D$35,341) -> 0 | K17: =SUMIFS(UCCo_IMC!M$3:M$35,UCCo_IMC!$C$3:$C$35,'Equipment Analysis'!$B17,UCCo_IMC!$D$3:$D$35,341) -> 0 | L17: =SUMIFS(UCCo_IMC!N$3:N$35,UCCo_IMC!$C$3:$C$35,'Equipment Analysis'!$B17,UCCo_IMC!$D$3:$D$35,341) -> 0 | M17: =SUMIFS(UCCo_IMC!O$3:O$35,UCCo_IMC!$C$3:$C$35,'Equipment Analysis'!$B17,UCCo_IMC!$D$3:$D$35,341) -> 0 | N17: =SUMIFS(UCCo_IMC!P$3:P$35,UCCo_IMC!$C$3:$C$35,'Equipment Analysis'!$B17,UCCo_IMC!$D$3:$D$35,341) -> 0 | O17: =SUM(C17:N17) -> -677927.45 | Q17: =+C17/(C$50+C$52+C$53) -> -0.4063812 | R17: =IFERROR(D17/(D$50+D$52+D$53),0) -> -0.6741006 | S17: =IFERROR(E17/(E$50+E$52+E$53),0) -> -0.17126036 | T17: =IFERROR(F17/(F$50+F$52+F$53),0) -> -3.7524059 | U17: =IFERROR(G17/(G$50+G$52+G$53),0) -> -1.7884456 | V17: =IFERROR(H17/(H$50+H$52+H$53),0) -> -2.3051374 | W17: =IFERROR(I17/(I$50+I$52+I$53),0) -> 0 | X17: =IFERROR(J17/(J$50+J$52+J$53),0) -> 0 | Y17: =IFERROR(K17/(K$50+K$52+K$53),0) -> 0 | ... AB17: =IFERROR(N17/(N$50+N$52+N$53),0) -> 0 | AC17: =+O17/(O$50+O$52+O$53) -> -0.79252822
A18: Fuel | B18: 7_Fuel | C18: 70699.49 | D18: 33613.37 | E18: 37401.29 | F18: 67150.34 | G18: -165.92 | H18: 26528.77 | I18: =SUMIFS(UCCo_IMC!K$3:K$35,UCCo_IMC!$C$3:$C$35,'Equipment Analysis'!$B18,UCCo_IMC!$D$3:$D$35,341) -> 23983.68 | J18: =SUMIFS(UCCo_IMC!L$3:L$35,UCCo_IMC!$C$3:$C$35,'Equipment Analysis'!$B18,UCCo_IMC!$D$3:$D$35,341) -> 19560.39 | K18: =SUMIFS(UCCo_IMC!M$3:M$35,UCCo_IMC!$C$3:$C$35,'Equipment Analysis'!$B18,UCCo_IMC!$D$3:$D$35,341) -> 18093.53 | L18: =SUMIFS(UCCo_IMC!N$3:N$35,UCCo_IMC!$C$3:$C$35,'Equipment Analysis'!$B18,UCCo_IMC!$D$3:$D$35,341) -> 30203.92 | M18: =SUMIFS(UCCo_IMC!O$3:O$35,UCCo_IMC!$C$3:$C$35,'Equipment Analysis'!$B18,UCCo_IMC!$D$3:$D$35,341) -> 0 | N18: =SUMIFS(UCCo_IMC!P$3:P$35,UCCo_IMC!$C$3:$C$35,'Equipment Analysis'!$B18,UCCo_IMC!$D$3:$D$35,341) -> 0 | O18: =SUM(C18:N18) -> 327068.86 | Q18: =+C18/(C$50+C$52+C$53) -> 0.91021378 | R18: =IFERROR(D18/(D$50+D$52+D$53),0) -> 0.57999085 | S18: =IFERROR(E18/(E$50+E$52+E$53),0) -> 0.63715193 | T18: =IFERROR(F18/(F$50+F$52+F$53),0) -> 0.82345608 | U18: =IFERROR(G18/(G$50+G$52+G$53),0) -> -0.0021926031 | V18: =IFERROR(H18/(H$50+H$52+H$53),0) -> 0.39223388 | W18: =IFERROR(I18/(I$50+I$52+I$53),0) -> 0.2013606 | X18: =IFERROR(J18/(J$50+J$52+J$53),0) -> 0.2035108 | Y18: =IFERROR(K18/(K$50+K$52+K$53),0) -> 0.16826455 | ... AB18: =IFERROR(N18/(N$50+N$52+N$53),0) -> 0 | AC18: =+O18/(O$50+O$52+O$53) -> 0.38235847
A19: Insurance/Taxes | B19: 7.1_Insurance/Taxes | C19: 160348.03 | D19: 97259.71 | E19: 128473.03 | F19: 146473.03 | G19: 159859.64 | H19: 158871.93 | I19: =SUMIFS(UCCo_IMC!K$3:K$35,UCCo_IMC!$C$3:$C$35,'Equipment Analysis'!$B19,UCCo_IMC!$D$3:$D$35,341) -> 165886.59 | J19: =SUMIFS(UCCo_IMC!L$3:L$35,UCCo_IMC!$C$3:$C$35,'Equipment Analysis'!$B19,UCCo_IMC!$D$3:$D$35,341) -> 160886.59 | K19: =SUMIFS(UCCo_IMC!M$3:M$35,UCCo_IMC!$C$3:$C$35,'Equipment Analysis'!$B19,UCCo_IMC!$D$3:$D$35,341) -> 165481.91 | L19: =SUMIFS(UCCo_IMC!N$3:N$35,UCCo_IMC!$C$3:$C$35,'Equipment Analysis'!$B19,UCCo_IMC!$D$3:$D$35,341) -> 167719.93 | M19: =SUMIFS(UCCo_IMC!O$3:O$35,UCCo_IMC!$C$3:$C$35,'Equipment Analysis'!$B19,UCCo_IMC!$D$3:$D$35,341) -> 0 | N19: =SUMIFS(UCCo_IMC!P$3:P$35,UCCo_IMC!$C$3:$C$35,'Equipment Analysis'!$B19,UCCo_IMC!$D$3:$D$35,341) -> 0 | O19: =SUM(C19:N19) -> 1511260.4 | Q19: =+C19/(C$50+C$52+C$53) -> 2.0643853 | R19: =IFERROR(D19/(D$50+D$52+D$53),0) -> 1.6781936 | S19: =IFERROR(E19/(E$50+E$52+E$53),0) -> 2.1886101 | T19: =IFERROR(F19/(F$50+F$52+F$53),0) -> 1.7961801 | U19: =IFERROR(G19/(G$50+G$52+G$53),0) -> 2.1125165 | V19: =IFERROR(H19/(H$50+H$52+H$53),0) -> 2.3489575 | W19: =IFERROR(I19/(I$50+I$52+I$53),0) -> 1.3927397 | X19: =IFERROR(J19/(J$50+J$52+J$53),0) -> 1.6739011 | Y19: =IFERROR(K19/(K$50+K$52+K$53),0) -> 1.5389335 | ... AB19: =IFERROR(N19/(N$50+N$52+N$53),0) -> 0 | AC19: =+O19/(O$50+O$52+O$53) -> 1.7667326
A20: DMV Fees | B20: 7.2_DMV Fees | C20: 53687.96 | D20: 103131 | E20: -7501 | F20: 5795.15 | G20: 4570.89 | H20: 153148.64 | I20: =SUMIFS(UCCo_IMC!K$3:K$35,UCCo_IMC!$C$3:$C$35,'Equipment Analysis'!$B20,UCCo_IMC!$D$3:$D$35,341) -> 31743 | J20: =SUMIFS(UCCo_IMC!L$3:L$35,UCCo_IMC!$C$3:$C$35,'Equipment Analysis'!$B20,UCCo_IMC!$D$3:$D$35,341) -> 54723.5 | K20: =SUMIFS(UCCo_IMC!M$3:M$35,UCCo_IMC!$C$3:$C$35,'Equipment Analysis'!$B20,UCCo_IMC!$D$3:$D$35,341) -> 87599 | L20: =SUMIFS(UCCo_IMC!N$3:N$35,UCCo_IMC!$C$3:$C$35,'Equipment Analysis'!$B20,UCCo_IMC!$D$3:$D$35,341) -> 86328.5 | M20: =SUMIFS(UCCo_IMC!O$3:O$35,UCCo_IMC!$C$3:$C$35,'Equipment Analysis'!$B20,UCCo_IMC!$D$3:$D$35,341) -> 0 | N20: =SUMIFS(UCCo_IMC!P$3:P$35,UCCo_IMC!$C$3:$C$35,'Equipment Analysis'!$B20,UCCo_IMC!$D$3:$D$35,341) -> 0 | O20: =SUM(C20:N20) -> 573226.64 | Q20: =+C20/(C$50+C$52+C$53) -> 0.69120047 | R20: =IFERROR(D20/(D$50+D$52+D$53),0) -> 1.7795013 | S20: =IFERROR(E20/(E$50+E$52+E$53),0) -> -0.12778374 | T20: =IFERROR(F20/(F$50+F$52+F$53),0) -> 0.071065187 | U20: =IFERROR(G20/(G$50+G$52+G$53),0) -> 0.060403493 | V20: =IFERROR(H20/(H$50+H$52+H$53),0) -> 2.2643374 | W20: =IFERROR(I20/(I$50+I$52+I$53),0) -> 0.26650578 | X20: =IFERROR(J20/(J$50+J$52+J$53),0) -> 0.5693559 | Y20: =IFERROR(K20/(K$50+K$52+K$53),0) -> 0.81464514 | ... AB20: =IFERROR(N20/(N$50+N$52+N$53),0) -> 0 | AC20: =+O20/(O$50+O$52+O$53) -> 0.67012818
A21: Other | B21: 8_Other | C21: -60897.82 | D21: -38515.45 | E21: -179.07 | F21: -10562.74 | G21: -10416.29 | H21: -52954.76 | I21: =SUMIFS(UCCo_IMC!K$3:K$35,UCCo_IMC!$C$3:$C$35,'Equipment Analysis'!$B21,UCCo_IMC!$D$3:$D$35,341) -> 37108.87 | J21: =SUMIFS(UCCo_IMC!L$3:L$35,UCCo_IMC!$C$3:$C$35,'Equipment Analysis'!$B21,UCCo_IMC!$D$3:$D$35,341) -> 64742.71 | K21: =SUMIFS(UCCo_IMC!M$3:M$35,UCCo_IMC!$C$3:$C$35,'Equipment Analysis'!$B21,UCCo_IMC!$D$3:$D$35,341) -> 104472.36 | L21: =SUMIFS(UCCo_IMC!N$3:N$35,UCCo_IMC!$C$3:$C$35,'Equipment Analysis'!$B21,UCCo_IMC!$D$3:$D$35,341) -> 67375.79 | M21: =SUMIFS(UCCo_IMC!O$3:O$35,UCCo_IMC!$C$3:$C$35,'Equipment Analysis'!$B21,UCCo_IMC!$D$3:$D$35,341) -> 0 | N21: =SUMIFS(UCCo_IMC!P$3:P$35,UCCo_IMC!$C$3:$C$35,'Equipment Analysis'!$B21,UCCo_IMC!$D$3:$D$35,341) -> 0 | O21: =SUM(C21:N21) -> 100173.6 | Q21: =+C21/(C$50+C$52+C$53) -> -0.78402312 | R21: =IFERROR(D21/(D$50+D$52+D$53),0) -> -0.6645751 | S21: =IFERROR(E21/(E$50+E$52+E$53),0) -> -0.0030505578 | T21: =IFERROR(F21/(F$50+F$52+F$53),0) -> -0.12952954 | U21: =IFERROR(G21/(G$50+G$52+G$53),0) -> -0.13764941 | V21: =IFERROR(H21/(H$50+H$52+H$53),0) -> -0.78294814 | W21: =IFERROR(I21/(I$50+I$52+I$53),0) -> 0.3115562 | X21: =IFERROR(J21/(J$50+J$52+J$53),0) -> 0.67359807 | Y21: =IFERROR(K21/(K$50+K$52+K$53),0) -> 0.97156247 | ... AB21: =IFERROR(N21/(N$50+N$52+N$53),0) -> 0 | AC21: =+O21/(O$50+O$52+O$53) -> 0.11710752
A22: Total Costs | C22: =SUM(C10:C21) -> 1906937.5 | D22: =SUM(D10:D21) -> 1767072.8 | E22: =SUM(E10:E21) -> 1608712.1 | F22: =SUM(F10:F21) -> 1828851.5 | G22: =SUM(G10:G21) -> 2014051 | H22: =SUM(H10:H21) -> 1835200.5 | I22: =SUM(I10:I21) -> 2264959.6 | J22: =SUM(J10:J21) -> 1959069.5 | ... O22: =SUM(O10:O21) -> 19855669 | Q22: =+C22/(C$50+C$52+C$53) -> 24.550684 | R22: =IFERROR(D22/(D$50+D$52+D$53),0) -> 30.490429 | S22: =IFERROR(E22/(E$50+E$52+E$53),0) -> 27.405313 | T22: =IFERROR(F22/(F$50+F$52+F$53),0) -> 22.426973 | U22: =IFERROR(G22/(G$50+G$52+G$53),0) -> 26.615324 | V22: =IFERROR(H22/(H$50+H$52+H$53),0) -> 27.133856 | W22: =IFERROR(I22/(I$50+I$52+I$53),0) -> 19.015998 | X22: =IFERROR(J22/(J$50+J$52+J$53),0) -> 20.38261 | Y22: =IFERROR(K22/(K$50+K$52+K$53),0) -> 21.672063 | ... AB22: =IFERROR(N22/(N$50+N$52+N$53),0) -> 0 | AC22: =+O22/(O$50+O$52+O$53) -> 23.212185
A25: Island Mechanical
C26: Equipment Costs | Q26: Equipment Costs per direct manhour
C27: January | D27: February | E27: March | F27: April | G27: May | H27: June | I27: July | J27: August | K27: September | L27: October | M27: November | N27: December | O27: YTD | Q27: January | R27: February | S27: March | T27: April | U27: May | V27: June | W27: July | X27: August | Y27: September | Z27: October | AA27: November | AB27: Dec | AC27: YTD
A28: Labor/Burden | B28: 2_Labor/Burden | C28: 20808.33 | D28: 14021.01 | E28: 19129.81 | F28: 15162.89 | G28: 14275.81 | H28: 11444.58 | I28: 12442.09 | J28: 35366.19 | K28: 36221.81 | L28: 32934.37 | M28: =SUMIFS(UCCo_IMC!O$3:O$35,UCCo_IMC!$C$3:$C$35,'Equipment Analysis'!$B28,UCCo_IMC!$D$3:$D$35,342) -> 0 | N28: =SUMIFS(UCCo_IMC!P$3:P$35,UCCo_IMC!$C$3:$C$35,'Equipment Analysis'!$B28,UCCo_IMC!$D$3:$D$35,342) -> 0 | O28: =SUM(C28:N28) -> 211806.89 | Q28: =+C28/C$51 -> 1.5622456 | R28: =IFERROR(D28/D$51,0) -> 1.461321 | S28: =IFERROR(E28/E$51,0) -> 1.9894764 | T28: =IFERROR(F28/F$51,0) -> 1.1680384 | U28: =IFERROR(G28/G$51,0) -> 1.7754878 | V28: =IFERROR(H28/H$51,0) -> 1.2016972 | W28: =IFERROR(I28/I$51,0) -> 1.0986218 | X28: =IFERROR(J28/J$51,0) -> 4.2155301 | Y28: =IFERROR(K28/K$51,0) -> 3.2303464 | ... AB28: =IFERROR(N28/N$51,0) -> 0 | AC28: =+O28/O$51 -> 2.0523651
A29: EQ Rentals | B29: 3_EQ Rentals | C29: 0 | D29: 0 | E29: 0 | F29: 0 | G29: 0 | H29: 0 | I29: 1800 | J29: -1800 | K29: 0 | L29: - | M29: =SUMIFS(UCCo_IMC!O$3:O$35,UCCo_IMC!$C$3:$C$35,'Equipment Analysis'!$B29,UCCo_IMC!$D$3:$D$35,341) -> 0 | N29: =SUMIFS(UCCo_IMC!P$3:P$35,UCCo_IMC!$C$3:$C$35,'Equipment Analysis'!$B29,UCCo_IMC!$D$3:$D$35,341) -> 0 | O29: =SUM(C29:N29) -> 0 | Q29: =+C29/C$51 -> 0 | R29: =IFERROR(D29/D$51,0) -> 0 | S29: =IFERROR(E29/E$51,0) -> 0 | T29: =IFERROR(F29/F$51,0) -> 0 | U29: =IFERROR(G29/G$51,0) -> 0 | V29: =IFERROR(H29/H$51,0) -> 0 | W29: =IFERROR(I29/I$51,0) -> 0.15893787 | X29: =IFERROR(J29/J$51,0) -> -0.21455391 | Y29: =IFERROR(K29/K$51,0) -> 0 | ... AB29: =IFERROR(N29/N$51,0) -> 0 | AC29: =+O29/O$51 -> 0
A30: EQ Leasing | B30: 4_EQ Leasing | C30: 11107.29 | D30: 12569.36 | E30: 9336.73 | F30: 16817.3 | G30: 16846.49 | H30: 10893.97 | I30: 14078.66 | J30: 10285.31 | K30: 10470.57 | L30: 20139.22 | M30: =SUMIFS(UCCo_IMC!O$3:O$35,UCCo_IMC!$C$3:$C$35,'Equipment Analysis'!$B30,UCCo_IMC!$D$3:$D$35,342) -> 0 | N30: =SUMIFS(UCCo_IMC!P$3:P$35,UCCo_IMC!$C$3:$C$35,'Equipment Analysis'!$B30,UCCo_IMC!$D$3:$D$35,342) -> 0 | O30: =SUM(C30:N30) -> 132544.9 | Q30: =+C30/C$51 -> 0.83391193 | R30: =IFERROR(D30/D$51,0) -> 1.3100248 | S30: =IFERROR(E30/E$51,0) -> 0.97100827 | T30: =IFERROR(F30/F$51,0) -> 1.295482 | U30: =IFERROR(G30/G$51,0) -> 2.0952043 | V30: =IFERROR(H30/H$51,0) -> 1.1438824 | W30: =IFERROR(I30/I$51,0) -> 1.243129 | X30: =IFERROR(J30/J$51,0) -> 1.2259741 | Y30: =IFERROR(K30/K$51,0) -> 0.93379013 | ... AB30: =IFERROR(N30/N$51,0) -> 0 | AC30: =+O30/O$51 -> 1.2843328
A31: Depreciation | B31: 5_Depreciation | C31: 52346.49 | D31: 52176.61 | E31: 52346.48 | F31: 52413.13 | G31: 52601.2 | H31: 52536.26 | I31: 52199.62 | J31: 52199.64 | K31: 52147.73 | L31: 52199.66 | M31: =SUMIFS(UCCo_IMC!O$3:O$35,UCCo_IMC!$C$3:$C$35,'Equipment Analysis'!$B31,UCCo_IMC!$D$3:$D$35,342) -> 0 | N31: =SUMIFS(UCCo_IMC!P$3:P$35,UCCo_IMC!$C$3:$C$35,'Equipment Analysis'!$B31,UCCo_IMC!$D$3:$D$35,342) -> 0 | O31: =SUM(C31:N31) -> 523166.82 | Q31: =+C31/C$51 -> 3.9300642 | R31: =IFERROR(D31/D$51,0) -> 5.4380375 | S31: =IFERROR(E31/E$51,0) -> 5.4439686 | T31: =IFERROR(F31/F$51,0) -> 4.0375249 | U31: =IFERROR(G31/G$51,0) -> 6.542031 | V31: =IFERROR(H31/H$51,0) -> 5.5163823 | W31: =IFERROR(I31/I$51,0) -> 4.6091647 | X31: =IFERROR(J31/J$51,0) -> 6.2220204 | Y31: =IFERROR(K31/K$51,0) -> 4.6506575 | ... AB31: =IFERROR(N31/N$51,0) -> 0 | AC31: =+O31/O$51 -> 5.0693786
A32: Outside Materials | B32: 6_Outside Materials | C32: 33098.49 | D32: 81670.9 | E32: 66954.33 | F32: 23213.12 | G32: 36256.1 | H32: 59153.49 | I32: 74106.43 | J32: 32739.2 | K32: 73521.49 | L32: -24445.13 | M32: =SUMIFS(UCCo_IMC!O$3:O$35,UCCo_IMC!$C$3:$C$35,'Equipment Analysis'!$B32,UCCo_IMC!$D$3:$D$35,342) -> 0 | N32: =SUMIFS(UCCo_IMC!P$3:P$35,UCCo_IMC!$C$3:$C$35,'Equipment Analysis'!$B32,UCCo_IMC!$D$3:$D$35,342) -> 0 | O32: =SUM(C32:N32) -> 456268.42 | Q32: =+C32/C$51 -> 2.4849649 | R32: =IFERROR(D32/D$51,0) -> 8.5120404 | S32: =IFERROR(E32/E$51,0) -> 6.9631668 | T32: =IFERROR(F32/F$51,0) -> 1.7881693 | U32: =IFERROR(G32/G$51,0) -> 4.5091848 | V32: =IFERROR(H32/H$51,0) -> 6.2112009 | W32: =IFERROR(I32/I$51,0) -> 6.5435101 | X32: =IFERROR(J32/J$51,0) -> 3.9024018 | Y32: =IFERROR(K32/K$51,0) -> 6.5568199 | ... AB32: =IFERROR(N32/N$51,0) -> 0 | AC32: =+O32/O$51 -> 4.4211469
A33: 3rd Party Labor | B33: 6.1_3rd Party Labor | C33: 2374.48 | D33: 40321.98 | E33: -8599.39 | F33: 28817.12 | G33: -41585.6 | H33: 1854.94 | I33: -13756.75 | J33: 1203.85 | K33: 0 | L33: 682.59 | M33: =SUMIFS(UCCo_IMC!O$3:O$35,UCCo_IMC!$C$3:$C$35,'Equipment Analysis'!$B33,UCCo_IMC!$D$3:$D$35,342) -> 0 | N33: =SUMIFS(UCCo_IMC!P$3:P$35,UCCo_IMC!$C$3:$C$35,'Equipment Analysis'!$B33,UCCo_IMC!$D$3:$D$35,342) -> 0 | O33: =SUM(C33:N33) -> 11313.22 | Q33: =+C33/C$51 -> 0.17827096 | R33: =IFERROR(D33/D$51,0) -> 4.2025045 | S33: =IFERROR(E33/E$51,0) -> -0.89432583 | T33: =IFERROR(F33/F$51,0) -> 2.2198606 | U33: =IFERROR(G33/G$51,0) -> -5.1720167 | V33: =IFERROR(H33/H$51,0) -> 0.19477135 | W33: =IFERROR(I33/I$51,0) -> -1.2147048 | X33: =IFERROR(J33/J$51,0) -> 0.14349484 | Y33: =IFERROR(K33/K$51,0) -> 0 | ... AB33: =IFERROR(N33/N$51,0) -> 0 | AC33: =+O33/O$51 -> 0.10962277
A34: Inventory Purchase | B34: 6.2_Inventory Purchase | C34: 0 | D34: 0 | E34: 0 | F34: 0 | G34: 0 | H34: 0 | I34: 0 | J34: 3649.54 | K34: 171.96 | L34: 926.71 | M34: =SUMIFS(UCCo_IMC!O$3:O$35,UCCo_IMC!$C$3:$C$35,'Equipment Analysis'!$B34,UCCo_IMC!$D$3:$D$35,341) -> 0 | N34: =SUMIFS(UCCo_IMC!P$3:P$35,UCCo_IMC!$C$3:$C$35,'Equipment Analysis'!$B34,UCCo_IMC!$D$3:$D$35,341) -> 0 | O34: =SUM(C34:N34) -> 4748.21 | Q34: =+C34/C$51 -> 0 | R34: =IFERROR(D34/D$51,0) -> 0 | S34: =IFERROR(E34/E$51,0) -> 0 | T34: =IFERROR(F34/F$51,0) -> 0 | U34: =IFERROR(G34/G$51,0) -> 0 | V34: =IFERROR(H34/H$51,0) -> 0 | W34: =IFERROR(I34/I$51,0) -> 0 | X34: =IFERROR(J34/J$51,0) -> 0.43501281 | Y34: =IFERROR(K34/K$51,0) -> 0.015335798 | ... AB34: =IFERROR(N34/N$51,0) -> 0 | AC34: =+O34/O$51 -> 0.046009176
A35: Fuel | B35: 7_Fuel | C35: 15160.62 | D35: 16398.61 | E35: 16404.62 | F35: 16404.61 | G35: 16404.62 | H35: 16406.86 | I35: 16405.74 | J35: 16405.74 | K35: 16405.74 | L35: 16418.29 | M35: =SUMIFS(UCCo_IMC!O$3:O$35,UCCo_IMC!$C$3:$C$35,'Equipment Analysis'!$B35,UCCo_IMC!$D$3:$D$35,342) -> 0 | N35: =SUMIFS(UCCo_IMC!P$3:P$35,UCCo_IMC!$C$3:$C$35,'Equipment Analysis'!$B35,UCCo_IMC!$D$3:$D$35,342) -> 0 | O35: =SUM(C35:N35) -> 162815.45 | Q35: =+C35/C$51 -> 1.1382274 | R35: =IFERROR(D35/D$51,0) -> 1.7091232 | S35: =IFERROR(E35/E$51,0) -> 1.70606 | T35: =IFERROR(F35/F$51,0) -> 1.2636914 | U35: =IFERROR(G35/G$51,0) -> 2.0402487 | V35: =IFERROR(H35/H$51,0) -> 1.7227437 | W35: =IFERROR(I35/I$51,0) -> 1.4486074 | X35: =IFERROR(J35/J$51,0) -> 1.9555087 | Y35: =IFERROR(K35/K$51,0) -> 1.4631026 | ... AB35: =IFERROR(N35/N$51,0) -> 0 | AC35: =+O35/O$51 -> 1.5776481
A36: Insurance/Taxes | B36: 7.1_Insurance/Taxes | C36: 4749.06 | D36: 1400.99 | E36: 15656 | F36: 8416.95 | G36: 2064.1 | H36: 5301.15 | I36: 7957.66 | J36: 3177.31 | K36: 10468.35 | L36: 7348.85 | M36: =SUMIFS(UCCo_IMC!O$3:O$35,UCCo_IMC!$C$3:$C$35,'Equipment Analysis'!$B36,UCCo_IMC!$D$3:$D$35,342) -> 0 | N36: =SUMIFS(UCCo_IMC!P$3:P$35,UCCo_IMC!$C$3:$C$35,'Equipment Analysis'!$B36,UCCo_IMC!$D$3:$D$35,342) -> 0 | O36: =SUM(C36:N36) -> 66540.42 | Q36: =+C36/C$51 -> 0.35654942 | R36: =IFERROR(D36/D$51,0) -> 0.14601631 | S36: =IFERROR(E36/E$51,0) -> 1.6282045 | T36: =IFERROR(F36/F$51,0) -> 0.64838039 | U36: =IFERROR(G36/G$51,0) -> 0.25671289 | V36: =IFERROR(H36/H$51,0) -> 0.55662832 | W36: =IFERROR(I36/I$51,0) -> 0.70265197 | X36: =IFERROR(J36/J$51,0) -> 0.3787246 | Y36: =IFERROR(K36/K$51,0) -> 0.93359214 | ... AB36: =IFERROR(N36/N$51,0) -> 0 | AC36: =+O36/O$51 -> 0.64476295
A37: DMV Fees | B37: 7.2_DMV Fees | C37: -2593.98 | D37: -27233.14 | E37: -2856.65 | F37: -27994.93 | G37: 66441.35 | H37: 1437.92 | I37: 3772.14 | J37: 7783.43 | K37: 6032.63 | L37: 7850.5 | M37: =SUMIFS(UCCo_IMC!O$3:O$35,UCCo_IMC!$C$3:$C$35,'Equipment Analysis'!$B37,UCCo_IMC!$D$3:$D$35,342) -> 0 | N37: =SUMIFS(UCCo_IMC!P$3:P$35,UCCo_IMC!$C$3:$C$35,'Equipment Analysis'!$B37,UCCo_IMC!$D$3:$D$35,342) -> 0 | O37: =SUM(C37:N37) -> 32639.27 | Q37: =+C37/C$51 -> -0.19475055 | R37: =IFERROR(D37/D$51,0) -> -2.8383376 | S37: =IFERROR(E37/E$51,0) -> -0.29708803 | T37: =IFERROR(F37/F$51,0) -> -2.1565251 | U37: =IFERROR(G37/G$51,0) -> 8.2633356 | V37: =IFERROR(H37/H$51,0) -> 0.15098365 | W37: =IFERROR(I37/I$51,0) -> 0.3330755 | X37: =IFERROR(J37/J$51,0) -> 0.92775851 | Y37: =IFERROR(K37/K$51,0) -> 0.53800417 | ... AB37: =IFERROR(N37/N$51,0) -> 0 | AC37: =+O37/O$51 -> 0.3162678
A38: Other | B38: 8_Other | C38: 19462.93 | D38: 39299.57 | E38: -6610.57 | F38: 0 | G38: 855.29 | H38: 0 | I38: 5746.83 | J38: -3971.04 | K38: 2855.29 | L38: 1758.35 | M38: =SUMIFS(UCCo_IMC!O$3:O$35,UCCo_IMC!$C$3:$C$35,'Equipment Analysis'!$B38,UCCo_IMC!$D$3:$D$35,342) -> 0 | N38: =SUMIFS(UCCo_IMC!P$3:P$35,UCCo_IMC!$C$3:$C$35,'Equipment Analysis'!$B38,UCCo_IMC!$D$3:$D$35,342) -> 0 | O38: =SUM(C38:N38) -> 59396.65 | Q38: =+C38/C$51 -> 1.4612358 | R38: =IFERROR(D38/D$51,0) -> 4.0959452 | S38: =IFERROR(E38/E$51,0) -> -0.68749103 | T38: =IFERROR(F38/F$51,0) -> 0 | U38: =IFERROR(G38/G$51,0) -> 0.10637274 | V38: =IFERROR(H38/H$51,0) -> 0 | W38: =IFERROR(I38/I$51,0) -> 0.50743829 | X38: =IFERROR(J38/J$51,0) -> -0.47333453 | Y38: =IFERROR(K38/K$51,0) -> 0.2546415 | ... AB38: =IFERROR(N38/N$51,0) -> 0 | AC38: =+O38/O$51 -> 0.57554129
A39: Total Costs | C39: =SUM(C28:C38) -> 156513.71 | D39: =SUM(D28:D38) -> 230625.89 | E39: =SUM(E28:E38) -> 161761.36 | F39: =SUM(F28:F38) -> 133250.19 | G39: =SUM(G28:G38) -> 164159.36 | H39: =SUM(H28:H38) -> 159029.17 | I39: =SUM(I28:I38) -> 174752.42 | J39: =SUM(J28:J38) -> 157039.17 | ... N39: =SUM(N28:N38) -> 0 | O39: =SUM(C39:N39) -> 1661240.2 | Q39: =+C39/C$51 -> 11.75072 | R39: =IFERROR(D39/D$51,0) -> 24.036675 | S39: =IFERROR(E39/E$51,0) -> 16.82298 | T39: =IFERROR(F39/F$51,0) -> 10.264622 | U39: =IFERROR(G39/G$51,0) -> 20.416561 | V39: =IFERROR(H39/H$51,0) -> 16.69829 | W39: =IFERROR(I39/I$51,0) -> 15.430432 | X39: =IFERROR(J39/J$51,0) -> 18.718537 | Y39: =IFERROR(K39/K$51,0) -> 18.57629 | ... AB39: =IFERROR(N39/N$51,0) -> 0 | AC39: =+O39/O$51 -> 16.097076
A42: Equipment Division Hours
A43: UCCo | C43: 6975.14 | D43: 6250.15 | E43: 5755.25 | F43: 5600.98 | G43: 6669.72 | H43: 4951.28 | I43: 8390.17 | J43: 5201.38 | K43: 5303.64 | L43: 6087.42 | O43: =SUM(C43:N43) -> 61185.13
A44: IMC | C44: 204 | D44: 157 | E44: 160 | F44: 167 | G44: 160 | H44: 171 | I44: 160 | J44: 160 | K44: 574 | L44: 656 | O44: =SUM(C44:N44) -> 2569
A45: Total | C45: =SUM(C43:C44) -> 7179.14 | D45: =SUM(D43:D44) -> 6407.15 | E45: =SUM(E43:E44) -> 5915.25 | F45: =SUM(F43:F44) -> 5767.98 | G45: =SUM(G43:G44) -> 6829.72 | H45: =SUM(H43:H44) -> 5122.28 | I45: =SUM(I43:I44) -> 8550.17 | J45: =SUM(J43:J44) -> 5361.38 | ... O45: =SUM(O43:O44) -> 63754.13
A48: Direct Manhours by Month
C49: January | D49: February | E49: March | F49: April | G49: May | H49: June | I49: July | J49: August | K49: September | L49: October | M49: November | N49: December | O49: YTD
A50: UCCo | C50: =+C58 -> 46832.5 | D50: =IF(D$62=0,0,D58-C58) -> 29660 | E50: =IF(E$62=0,0,E58-D58) -> 33784.74 | F50: =IF(F$62=0,0,F58-E58) -> 41821.36 | G50: =IF(G$62=0,0,G58-F58) -> 33374.11 | H50: =IF(H$62=0,0,H58-G58) -> 29421.83 | I50: =IF(I$62=0,0,I58-H58) -> 47870.81 | J50: =IF(J$62=0,0,J58-I58) -> 44494.25 | K50: =IF(K$62=0,0,K58-J58) -> 56126.755 | ... N50: =IF(N$62=0,0,N58-M58) -> 0 | O50: =SUM(C50:N50) -> 408716
...

Sheet UCCo_IMC
A1: 2025 Equipment Rollup Summary
A3: Company Name | B3: Indirect Cost Type | C3: Equipment Cost Category | D3: Company Number | E3: January | F3: February | G3: March | H3: April | I3: May | J3: June | K3: July | L3: August | M3: September | N3: October | O3: November | P3: December | Q3: Year To Date
A4: UNDERGROUND CONSTRUCTION CO. | B4: 1_Income | C4: 1_Income Owned | D4: 341 | E4: =E6-E5 -> -1304163.5 | F4: =F6-F5 -> -1070090 | G4: =G6-G5 -> -1147555.1 | H4: =H6-H5 -> -1240827.6 | I4: =I6-I5 -> -1574838.6 | J4: =J6-J5 -> -1378198.7 | K4: =K6-K5 -> -2531909.9 | L4: =L6-L5 -> -1998261.1 | ... P4: =P6-P5 -> 0 | Q4: =SUM(E4:P4) -> -16992463
C5: 1_Income Rental | D5: 341 | E5: -571652.55 | F5: -357987.95 | G5: -404997.79 | H5: -485651.93 | I5: -727729.92 | J5: -632662.17 | Q5: =SUM(E5:P5) -> -3180682.3
B6: 1_Income - Total | E6: -1875816.1 | F6: -1428077.9 | G6: -1552552.9 | H6: -1726479.5 | I6: -2302568.5 | J6: -2010860.9 | K6: -2531909.9 | L6: -1998261.1 | M6: -2025180.5 | N6: -2721438 | O6: 0 | P6: 0 | Q6: =SUM(Q4:Q5) -> -20173145
B7: 2_Cost | C7: 2_Labor/Burden | D7: 341 | E7: 592255.76 | F7: 563050.61 | G7: 525361.62 | H7: 494097.23 | I7: 574141.77 | J7: 513722.69 | K7: 740150.95 | L7: 570230.96 | M7: 653440.65 | N7: 675553.09 | O7: 0 | P7: 0 | Q7: =SUM(E7:P7) -> 5902005.3
C8: 3_EQ Rentals | D8: 341 | E8: 293422.21 | F8: 231941.64 | G8: 49706.42 | H8: 340243.92 | I8: 406620.5 | J8: -9864.56 | K8: 739131.43 | L8: 251897.61 | M8: 435893.39 | N8: 344975.35 | O8: 0 | P8: 0 | Q8: =SUM(E8:P8) -> 3083967.9
C9: 4_EQ Leasing | D9: 341 | E9: 392435.02 | F9: 403947.87 | G9: 407412.74 | H9: 388972.38 | I9: 395347.45 | J9: 391476.87 | K9: 394134.84 | L9: 444552.79 | M9: 392068.76 | N9: 411163.05 | O9: 0 | P9: 0 | Q9: =SUM(E9:P9) -> 4021511.8
C10: 5_Depreciation | D10: 341 | E10: 163566.12 | F10: 161170.72 | G10: 154781.97 | H10: 153255.73 | I10: 148043.93 | J10: 145367.08 | K10: 144944.34 | L10: 142161.16 | M10: 149636.58 | N10: 145525.25 | O10: 0 | P10: 0 | Q10: =SUM(E10:P10) -> 1508452.9
C11: 6.1_3rd Party Labor | D11: 341 | E11: 159961.8 | F11: 148228.09 | G11: 183422.89 | H11: 285506.97 | I11: 206232.72 | J11: 208505.27 | K11: 302633.14 | L11: 94383.24 | M11: 331233.84 | N11: 59879.37 | O11: 0 | P11: 0 | Q11: =SUM(E11:P11) -> 1979987.3
C12: 6.2_Inventory Purchase | D12: 341 | E12: 67146.61 | F12: 53365.56 | G12: 106221.08 | H12: -64252.58 | I12: 112042.77 | J12: 276443.29 | K12: -466840.38 | L12: -120205.35 | M12: -110116.2 | N12: -128248.1 | O12: 0 | P12: 0 | Q12: =SUM(E12:P12) -> -274443.3
C13: 6_Outside Materials | D13: 341 | E13: 16062.34 | F13: 11679.67 | G13: 25411.16 | H13: 23972.05 | I13: 19573.58 | J13: 24830.28 | K13: 152083.11 | L13: 276135.89 | M13: 102598.69 | N13: 479935.34 | O13: 0 | P13: 0 | Q13: =SUM(E13:P13) -> 1132282.1
C14: 7.1_Insurance/Taxes | D14: 341 | E14: 160348.03 | F14: 97259.71 | G14: 128473.03 | H14: 146473.03 | I14: 159859.64 | J14: 158871.93 | K14: 165886.59 | L14: 160886.59 | M14: 165481.91 | N14: 167719.93 | O14: 0 | P14: 0 | Q14: =SUM(E14:P14) -> 1511260.4
C15: 7.2_DMV Fees | D15: 341 | E15: 53687.96 | F15: 103131 | G15: -7501 | H15: 5795.15 | I15: 4570.89 | J15: 153148.64 | K15: 31743 | L15: 54723.5 | M15: 87599 | N15: 86328.5 | O15: 0 | P15: 0 | Q15: =SUM(E15:P15) -> 573226.64
C16: 7_Fuel | D16: 341 | E16: 70699.49 | F16: 33613.37 | G16: 37401.29 | H16: 67150.34 | I16: -165.92 | J16: 26528.77 | K16: 23983.68 | L16: 19560.39 | M16: 18093.53 | N16: 30203.92 | O16: 0 | P16: 0 | Q16: =SUM(E16:P16) -> 327068.86
C17: 8_Other | D17: 341 | E17: -62647.82 | F17: -40315.45 | G17: -1979.07 | H17: -12362.74 | I17: -12216.29 | J17: -53829.76 | K17: 37108.87 | L17: 64742.71 | M17: 104472.36 | N17: 67375.79 | O17: 0 | P17: 0 | Q17: =SUM(E17:P17) -> 90348.6
B18: 2_Cost - Total | E18: =SUM(E7:E17) -> 1906937.5 | F18: =SUM(F7:F17) -> 1767072.8 | G18: =SUM(G7:G17) -> 1608712.1 | H18: =SUM(H7:H17) -> 1828851.5 | I18: =SUM(I7:I17) -> 2014051 | J18: =SUM(J7:J17) -> 1835200.5 | K18: =SUM(K7:K17) -> 2264959.6 | L18: =SUM(L7:L17) -> 1959069.5 | ... Q18: =SUM(Q7:Q17) -> 19855669
A19: UNDERGROUND CONSTRUCTION CO. - Total | E19: =+E6+E18 -> 31121.45 | F19: =+F6+F18 -> 338994.84 | G19: =+G6+G18 -> 56159.24 | H19: =+H6+H18 -> 102371.98 | I19: =+I6+I18 -> -288517.44 | J19: =+J6+J18 -> -175660.38 | K19: =+K6+K18 -> -266950.3 | L19: =+L6+L18 -> -39191.64 | ... Q19: =+Q6+Q18 -> -317476.77
A20: ISLAND MECHANICAL CORPORATION | B20: 1_Income | C20: 1_Income | D20: 342 | E20: -149306.21 | F20: -95480.04 | G20: -88144.87 | H20: -120380.08 | I20: -89382.74 | J20: -85041.53 | K20: -68217.8 | L20: -86663.37 | M20: =+M21 -> -154882.82 | N20: =+N21 -> -202100.96 | O20: =+O21 -> 0 | P20: =+P21 -> 0 | Q20: =SUM(E20:P20) -> -1139600.4
B21: 1_Income - Total | E21: =E20 -> -149306.21 | F21: =F20 -> -95480.04 | G21: =G20 -> -88144.87 | H21: =H20 -> -120380.08 | I21: =I20 -> -89382.74 | J21: =J20 -> -85041.53 | K21: =K20 -> -68217.8 | L21: =L20 -> -86663.37 | M21: -154882.82 | N21: -202100.96 | O21: 0 | P21: 0 | Q21: =SUM(E21:P21) -> -1139600.4
B22: 2_Cost | C22: 2_Labor/Burden | D22: 342 | E22: 20808.33 | F22: 14021.01 | G22: 19129.81 | H22: 15162.89 | I22: 14275.81 | J22: 11444.58 | K22: 12442.09 | L22: 35366.19 | M22: 36221.81 | N22: 32934.37 | O22: 0 | P22: 0 | Q22: =SUM(E22:P22) -> 211806.89
C23: 3_EQ Rentals | D23: 342 | E23: 0 | F23: 0 | G23: 0 | H23: 0 | I23: 0 | J23: 0 | K23: 1800 | L23: -1800 | M23: 0 | N23: - | O23: 0 | P23: 0 | Q23: =SUM(E23:P23) -> 0
C24: 4_EQ Leasing | D24: 342 | E24: 11107.29 | F24: 12569.36 | G24: 9336.73 | H24: 16817.3 | I24: 16846.49 | J24: 10893.97 | K24: 14078.66 | L24: 10285.31 | M24: 10470.57 | N24: 20139.22 | O24: 0 | P24: 0 | Q24: =SUM(E24:P24) -> 132544.9
C25: 5_Depreciation | D25: 342 | E25: 52346.49 | F25: 52176.61 | G25: 52346.48 | H25: 52413.13 | I25: 52601.2 | J25: 52536.26 | K25: 52199.62 | L25: 52199.64 | M25: 52147.73 | N25: 52199.66 | O25: 0 | P25: 0 | Q25: =SUM(E25:P25) -> 523166.82
C26: 6.1_3rd Party Labor | D26: 342 | E26: 33098.49 | F26: 81670.9 | G26: 66954.33 | H26: 23213.12 | I26: 36256.1 | J26: 59153.49 | K26: 74106.43 | L26: 32739.2 | M26: 73521.49 | N26: -24445.13 | O26: 0 | P26: 0 | Q26: =SUM(E26:P26) -> 456268.42
C27: 6.2_Inventory Purchase | D27: 342 | E27: 2374.48 | F27: 40321.98 | G27: -8599.39 | H27: 28817.12 | I27: -41585.6 | J27: 1854.94 | K27: -13756.75 | L27: 1203.85 | M27: 0 | N27: 682.59 | O27: 0 | P27: 0 | Q27: =SUM(E27:P27) -> 11313.22
C28: 6_Outside Materials | D28: 342 | E28: 0 | F28: 0 | G28: 0 | H28: 0 | I28: 0 | J28: 0 | K28: 0 | L28: 3649.54 | M28: 171.96 | N28: 926.71 | O28: 0 | P28: 0 | Q28: =SUM(E28:P28) -> 4748.21
C29: 7.1_Insurance/Taxes | D29: 342 | E29: 15160.62 | F29: 16398.61 | G29: 16404.62 | H29: 16404.61 | I29: 16404.62 | J29: 16406.86 | K29: 16405.74 | L29: 16405.74 | M29: 16405.74 | N29: 16418.29 | O29: 0 | P29: 0 | Q29: =SUM(E29:P29) -> 162815.45
C30: 7.2_DMV Fees | D30: 342 | E30: 4749.06 | F30: 1400.99 | G30: 15656 | H30: 8416.95 | I30: 2064.1 | J30: 5301.15 | K30: 7957.66 | L30: 3177.31 | M30: 10468.35 | N30: 7348.85 | O30: 0 | P30: 0 | Q30: =SUM(E30:P30) -> 66540.42
C31: 7_Fuel | D31: 342 | E31: -2593.98 | F31: -27233.14 | G31: -2856.65 | H31: -27994.93 | I31: 66441.35 | J31: 1437.92 | K31: 3772.14 | L31: 7783.43 | M31: 6032.63 | N31: 7850.5 | O31: 0 | P31: 0 | Q31: =SUM(E31:P31) -> 32639.27
C32: 8_Other | D32: 342 | E32: 19462.93 | F32: 39299.57 | G32: -6610.57 | H32: 0 | I32: 855.29 | J32: 0 | K32: 5746.83 | L32: -3971.04 | M32: 2855.29 | N32: 1758.35 | O32: 0 | P32: 0 | Q32: =SUM(E32:P32) -> 59396.65
B33: 2_Cost - Total | E33: =SUM(E22:E32) -> 156513.71 | F33: =SUM(F22:F32) -> 230625.89 | G33: =SUM(G22:G32) -> 161761.36 | H33: =SUM(H22:H32) -> 133250.19 | I33: =SUM(I22:I32) -> 164159.36 | J33: =SUM(J22:J32) -> 159029.17 | K33: =SUM(K22:K32) -> 174752.42 | L33: =SUM(L22:L32) -> 157039.17 | ... Q33: =SUM(Q22:Q32) -> 1661240.2
A34: ISLAND MECHANICAL CORPORATION - Total | E34: =+E33+E21 -> 7207.5 | F34: =+F33+F21 -> 135145.85 | G34: =+G33+G21 -> 73616.49 | H34: =+H33+H21 -> 12870.11 | I34: =+I33+I21 -> 74776.62 | J34: =+J33+J21 -> 73987.64 | K34: =+K33+K21 -> 106534.62 | L34: =+L33+L21 -> 70375.8 | ... Q34: =+Q33+Q21 -> 521639.83
A35: Overall - Total | E35: =+E34+E19 -> 38328.95 | F35: =+F34+F19 -> 474140.69 | G35: =+G34+G19 -> 129775.73 | H35: =+H34+H19 -> 115242.09 | I35: =+I34+I19 -> -213740.82 | J35: =+J34+J19 -> -101672.74 | K35: =+K34+K19 -> -160415.68 | L35: =+L34+L19 -> 31184.16 | ... Q35: =+Q34+Q19 -> 204163.06
B40: Direct Equipment Rental Expense | E40: 1116025.4 | F40: 788028.28 | G40: 923829.67 | H40: 744578.13 | I40: 770675.92 | J40: 659218.25 | K40: =2772566.3/2 -> 1386283.1 | L40: =2772566.3/2 -> 1386283.1 | M40: 3023481.1 | N40: 779256.31 | Q40: =SUM(E40:P40) -> 11577659
B41: Direct Fuel Expense | E41: 419897.83 | F41: 378109.18 | G41: 379854.49 | H41: 423269.9 | I41: 456971.24 | J41: 516135.88 | K41: 571035.34 | L41: 571035.34 | M41: 609284.85 | N41: =-25183.16+619599.93 -> 594416.77 | Q41: =SUM(E41:P41) -> 4920010.8

Sheet Graph Data
A8: Manhours
B9: Jan-24 | C9: Feb-24 | D9: Mar-24 | E9: Apr-24 | F9: May-24 | G9: Jun-24 | H9: Jul-24 | I9: Aug-24 | J9: Sep-24 | K9: Oct-24 | L9: Nov-24 | M9: Dec-24 | N9: Jan-25 | O9: Feb-25 | P9: Mar-25 | Q9: Apr-25 | R9: May-25 | S9: Jun-25 | T9: Jul-25 | U9: Aug-25 | V9: Sept-25 | W9: 45955
A10: Fleet Costs | B10: 2257.1126 | C10: 2198.8809 | D10: 2074.0676 | E10: 2191.6957 | F10: 2193.1301 | G10: 2025.5822 | H10: 2061.5743 | I10: 1987.5133 | J10: 2166.1072 | K10: 2352.7451 | L10: 1904.4864 | M10: 1868.0132 | N10: 1906.9375 | O10: 1767.0728 | P10: 1608.7121 | Q10: 1828.8515 | R10: 2014.051 | S10: 1835.2005 | T10: =+'[1]Equipment Analysis'!I22/1000 -> 2264.9596 | U10: =+'[1]Equipment Analysis'!J22/1000 -> 1959.0695 | V10: =+'[1]Equipment Analysis'!K22/1000 -> 2330.4025 | W10: =+'Equipment Analysis'!L22/1000 -> 2340.4115
A11: $/DMH | B11: =+B10/B12 -> 42.622632 | C11: =+C10/C12 -> 26.529042 | D11: =+D10/D12 -> 27.034446 | E11: =+E10/E12 -> 32.622771 | F11: =+F10/F12 -> 23.053627 | G11: =+G10/G12 -> 23.268312 | H11: =+H10/H12 -> 26.076033 | I11: =+I10/I12 -> 16.114315 | ... R11: =+R10/R12 -> 26.615324 | S11: 27.133856 | T11: =+T10/T12 -> 19.015998 | U11: =+U10/U12 -> 20.38261 | V11: =+V10/V12 -> 21.672063 | W11: =+W10/W12 -> 20.627363
A12: MH | B12: 52.95573 | C12: 82.8858 | D12: 76.71944 | E12: 67.183 | F12: 95.13167 | G12: 87.05325 | H12: 79.06012 | I12: 123.33837 | J12: 103.12676 | K12: 133.40735 | L12: 86.33966 | M12: 75.69867 | N12: 77.6735 | O12: 57.955 | P12: 58.70074 | Q12: 81.54696 | R12: 75.67261 | S12: 67.63508 | T12: =(+'[1]Equipment Analysis'!I50+'[1]Equipment Analysis'!I52)/1000 -> 119.10811 | U12: =(+'[1]Equipment Analysis'!J50+'[1]Equipment Analysis'!J52)/1000 -> 96.11475 | V12: =(+'[1]Equipment Analysis'!K50+'[1]Equipment Analysis'!K52)/1000 -> 107.53025 | W12: =(+'Equipment Analysis'!L50+'Equipment Analysis'!L52)/1000 -> 113.46149
B14: Jan-24 | C14: Feb-24 | D14: Mar-24 | E14: Apr-24 | F14: May-24 | G14: Jun-24 | H14: Jul-24 | I14: Aug-24 | J14: Sep-24 | K14: Oct-24 | L14: Nov-24 | M14: Dec-24 | N14: Jan-25 | O14: Feb-25 | P14: Mar-25 | Q14: Apr-25 | R14: May-25 | S14: Jun-25 | T14: Jul-25 | U14: Aug-25 | V14: Sept-25 | W14: 45955
A15: Fleet Costs | B15: 101.6986 | C15: 153.64859 | D15: 217.42003 | E15: 195.91162 | F15: 154.84662 | G15: 116.96908 | H15: 150.35442 | I15: 100.10326 | J15: 239.58982 | K15: 163.8444 | L15: 168.67701 | M15: 156.65853 | N15: 156.51371 | O15: 230.62589 | P15: 161.76136 | Q15: 133.25019 | R15: 164.15936 | S15: 159.02917 | T15: =+'[1]Equipment Analysis'!I39/1000 -> 174.75242 | U15: =+'[1]Equipment Analysis'!J39/1000 -> 157.03917 | V15: =+'[1]Equipment Analysis'!K39/1000 -> 208.29557 | W15: =+'Equipment Analysis'!L39/1000 -> 115.81341
A16: $/DMH | B16: =+B15/B17 -> 11.628013 | C16: =+C15/C17 -> 14.180111 | D16: =+D15/D17 -> 26.777515 | E16: =+E15/E17 -> 26.444168 | F16: =+F15/F17 -> 16.009783 | G16: =+G15/G17 -> 14.690917 | H16: =+H15/H17 -> 16.841716 | I16: =+I15/I17 -> 7.7171692 | ... R16: =+R15/R17 -> 20.416561 | S16: 16.69829 | T16: =+T15/T17 -> 15.430432 | U16: =+U15/U17 -> 18.718537 | V16: =+V15/V17 -> 18.57629 | W16: =+W15/W17 -> 12.590768
A17: MH | B17: 8.746 | C17: 10.8355 | D17: 8.1195 | E17: 7.4085 | F17: 9.672 | G17: 7.962 | H17: 8.9275 | I17: 12.9715 | J17: 10.0025 | K17: 11.84475 | L17: 11.263 | M17: 9.782 | N17: 13.3195 | O17: 9.59475 | P17: 9.6155 | Q17: 12.9815 | R17: 8.0405 | S17: 9.52368 | T17: =+'[1]Equipment Analysis'!I51/1000 -> 11.32518 | U17: =+'[1]Equipment Analysis'!J51/1000 -> 8.3895 | V17: =+'[1]Equipment Analysis'!K51/1000 -> 11.21298 | W17: =+'Equipment Analysis'!L51/1000 -> 9.19828
B19: =+B15/1000 -> 0.1016986 | C19: =+C15/1000 -> 0.15364859 | D19: =+D15/1000 -> 0.21742003 | E19: =+E15/1000 -> 0.19591162 | F19: =+F15/1000 -> 0.15484662 | G19: =+G15/1000 -> 0.11696908 | H19: =+H15/1000 -> 0.15035442 | I19: =+I15/1000 -> 0.10010326 | ... R19: =+R15/1000 -> 0.16415936
B20: =+B17/1000 -> 0.008746 | C20: =+C17/1000 -> 0.0108355 | D20: =+D17/1000 -> 0.0081195 | E20: =+E17/1000 -> 0.0074085 | F20: =+F17/1000 -> 0.009672 | G20: =+G17/1000 -> 0.007962 | H20: =+H17/1000 -> 0.0089275 | I20: =+I17/1000 -> 0.0129715 | ... R20: =+R17/1000 -> 0.0080405
B26: Q1-24 | C26: Q2-24 | D26: Q3-24 | E26: Q4-24 | F26: Q1-25 | G26: Q2-25 | H26: Q3-25 | I26: 45955
A27: Fleet Costs | B27: =SUM(B10:D10) -> 6530.0611 | C27: =SUM(E10:G10) -> 6410.4079 | D27: =SUM(H10:J10) -> 6215.1948 | E27: =SUM(K10:M10) -> 6125.2447 | F27: =SUM(N10:P10) -> 5282.7224 | G27: =SUM(Q10:S10) -> 5678.103 | H27: =SUM(T10:V10) -> 6554.4316 | I27: =+W10 -> 2340.4115
A28: $/DMH | B28: =+B27/B29 -> 30.720885 | C28: =+C27/C29 -> 25.706626 | D28: =+D27/D29 -> 20.342655 | E28: =+E27/E29 -> 20.73222 | F28: =+F27/F29 -> 27.184393 | G28: =+G27/G29 -> 25.252326 | H28: =+H27/H29 -> 20.30788 | I28: =+W11 -> 20.627363
A29: MH | B29: =SUM(B12:D12) -> 212.56097 | C29: =SUM(E12:G12) -> 249.36792 | D29: =SUM(H12:J12) -> 305.52525 | E29: =SUM(K12:M12) -> 295.44568 | F29: =SUM(N12:P12) -> 194.32924 | G29: =SUM(Q12:S12) -> 224.85465 | H29: =SUM(T12:V12) -> 322.75311 | I29: =+W12 -> 113.46149
B32: Q1-24 | C32: Q2-24 | D32: Q3-24 | E32: Q4-24 | F32: Q1-25 | G32: Q2-25 | H32: Q3-25 | I32: 45955
A33: Fleet Costs | B33: =SUM(B15:D15) -> 472.76722 | C33: =SUM(E15:G15) -> 467.72732 | D33: =SUM(H15:J15) -> 490.0475 | E33: =SUM(K15:M15) -> 489.17994 | F33: =SUM(N15:P15) -> 548.90096 | G33: =SUM(Q15:S15) -> 456.43872 | H33: =SUM(T15:V15) -> 540.08716 | I33: =+W15 -> 115.81341
A34: $/DMH | B34: =+B33/B35 -> 17.066793 | C34: =+C33/C35 -> 18.677341 | D34: =+D33/D35 -> 15.361268 | E34: =+E33/E35 -> 14.873325 | F34: =+F33/F35 -> 16.873814 | G34: =+G33/G35 -> 14.942824 | H34: =+H33/H35 -> 17.462917 | I34: =+W16 -> 12.590768
A35: MH | B35: =SUM(B17:D17) -> 27.701 | C35: =SUM(E17:G17) -> 25.0425 | D35: =SUM(H17:J17) -> 31.9015 | E35: =SUM(K17:M17) -> 32.88975 | F35: =SUM(N17:P17) -> 32.52975 | G35: =SUM(Q17:S17) -> 30.54568 | H35: =SUM(T17:V17) -> 30.92766 | I35: =+W17 -> 9.19828
