Workbook

Sheet Sheet2

Sheet Sheet1
A3: Division | C3: Jan | D3: Feb | E3: March | F3: April | G3: May | H3: June | I3: July | J3: Aug | K3: Sept | L3: Oct
A4: Elec | C4: =VLOOKUP(A4,sept!A$111:C$120,3,FALSE) -> 31067.019 | D4: =VLOOKUP($A4,sept!$A$96:$C$106,3,FALSE) -> 33451.662 | E4: =VLOOKUP($A4,sept!$A$82:$C$92,3,FALSE) -> 34936.85 | F4: =VLOOKUP($A4,sept!$A$68:$C$78,3,FALSE) -> 43696.177 | G4: =VLOOKUP($A4,sept!$A$54:$C$64,3,FALSE) -> 51280.472 | H4: =VLOOKUP($A4,sept!$A$42:$C$50,3,FALSE) -> 60046.593 | I4: =VLOOKUP($A4,sept!$A$28:$C$38,3,FALSE) -> 65573.818 | J4: =VLOOKUP($A4,sept!$A$16:$C$23,3,FALSE) -> 69050.33 | K4: =VLOOKUP($A4,sept!$A$1:$C$9,3,FALSE) -> 61022 | L4: =+sept!C127 -> 50110.787
A5: Gas Tran | C5: =VLOOKUP(A5,sept!A$111:C$120,3,FALSE) -> 18422.097 | D5: =VLOOKUP($A5,sept!$A$96:$C$106,3,FALSE) -> 11169.875 | E5: =VLOOKUP($A5,sept!$A$82:$C$92,3,FALSE) -> 6691.94 | F5: =VLOOKUP($A5,sept!$A$68:$C$78,3,FALSE) -> 9913.542 | G5: =VLOOKUP($A5,sept!$A$54:$C$64,3,FALSE) -> 11049.901 | H5: =VLOOKUP($A5,sept!$A$42:$C$50,3,FALSE) -> 13558.782 | I5: =VLOOKUP($A5,sept!$A$28:$C$38,3,FALSE)+VLOOKUP("Gas Transmission",sept!$A$28:$C$38,3,FALSE) -> 15004.701 | J5: =VLOOKUP($A5,sept!$A$16:$C$23,3,FALSE)+VLOOKUP("gas transmission",sept!$A$16:$C$23,3,FALSE) -> 25182.163 | K5: =VLOOKUP($A5,sept!$A$1:$C$9,3,FALSE)+VLOOKUP("gas transmission",sept!$A$1:$C$9,3,FALSE) -> 20313 | L5: =VLOOKUP(A5,sept!$A$126:$D$136,3,FALSE) -> 17655.18
A6: So Cal | C6: =VLOOKUP(A6,sept!A$111:C$120,3,FALSE) -> 14834.043 | D6: =VLOOKUP($A6,sept!$A$96:$C$106,3,FALSE) -> 10691.402 | E6: =VLOOKUP($A6,sept!$A$82:$C$92,3,FALSE) -> 12247.506 | F6: =VLOOKUP($A6,sept!$A$68:$C$78,3,FALSE) -> 9149.496 | G6: =VLOOKUP($A6,sept!$A$54:$C$64,3,FALSE) -> 6241.404 | H6: =VLOOKUP($A6,sept!$A$42:$C$50,3,FALSE) -> 9061.299 | I6: =VLOOKUP($A6,sept!$A$28:$C$38,3,FALSE) -> 10918.678 | J6: =VLOOKUP($A6,sept!$A$16:$C$23,3,FALSE) -> 7468.971 | K6: =VLOOKUP($A6,sept!$A$1:$C$9,3,FALSE) -> 4357 | L6: =VLOOKUP(A6,sept!$A$126:$D$136,3,FALSE) -> 8351.205
A7: San Diego | C7: =VLOOKUP(A7,sept!A$111:C$120,3,FALSE) -> 9804.487 | D7: =VLOOKUP($A7,sept!$A$96:$C$106,3,FALSE) -> 8081.073 | E7: =VLOOKUP($A7,sept!$A$82:$C$92,3,FALSE) -> 6920.586 | F7: =VLOOKUP($A7,sept!$A$68:$C$78,3,FALSE) -> 6847.577 | G7: =VLOOKUP($A7,sept!$A$54:$C$64,3,FALSE) -> 6214.532 | H7: =VLOOKUP($A7,sept!$A$42:$C$50,3,FALSE) -> 6098.984 | I7: =VLOOKUP($A7,sept!$A$28:$C$38,3,FALSE) -> 3938.689 | J7: =VLOOKUP($A7,sept!$A$16:$C$23,3,FALSE) -> 7957.965 | K7: =VLOOKUP($A7,sept!$A$1:$C$9,3,FALSE) -> 13026 | L7: =VLOOKUP(A7,sept!$A$126:$D$136,3,FALSE) -> 10546.275
A8: Fuel | C8: =VLOOKUP(A8,sept!A$111:C$120,3,FALSE) -> 5008.59 | D8: =VLOOKUP($A8,sept!$A$96:$C$106,3,FALSE) -> 3974.292 | E8: =VLOOKUP($A8,sept!$A$82:$C$92,3,FALSE) -> 4164.305 | F8: =VLOOKUP($A8,sept!$A$68:$C$78,3,FALSE) -> 3952.853 | G8: =VLOOKUP($A8,sept!$A$54:$C$64,3,FALSE) -> 3878.208 | H8: =VLOOKUP($A8,sept!$A$42:$C$50,3,FALSE) -> 3005.399 | I8: =VLOOKUP($A8,sept!$A$28:$C$38,3,FALSE) -> 2786.463 | J8: =VLOOKUP($A8,sept!$A$16:$C$23,3,FALSE) -> 2391.05 | K8: =VLOOKUP($A8,sept!$A$1:$C$9,3,FALSE) -> 2448 | L8: =+sept!C132 -> 1814.331
A9: Gas Dist | C9: =VLOOKUP(A9,sept!A$111:C$120,3,FALSE) -> 4190.815 | D9: =VLOOKUP($A9,sept!$A$96:$C$106,3,FALSE) -> 2481.663 | E9: =VLOOKUP($A9,sept!$A$82:$C$92,3,FALSE) -> 3307.134 | F9: =VLOOKUP($A9,sept!$A$68:$C$78,3,FALSE) -> 3018.949 | G9: =VLOOKUP($A9,sept!$A$54:$C$64,3,FALSE) -> 2590.716 | H9: =VLOOKUP($A9,sept!$A$42:$C$50,3,FALSE) -> 3773.619 | I9: =VLOOKUP($A9,sept!$A$28:$C$38,3,FALSE) -> 3466.619 | J9: =VLOOKUP($A9,sept!$A$16:$C$23,3,FALSE) -> 2756.955 | K9: =VLOOKUP($A9,sept!$A$1:$C$9,3,FALSE) -> 2472 | L9: =VLOOKUP(A9,sept!$A$126:$D$136,3,FALSE) -> 4578.711
A10: Major Projects | C10: =VLOOKUP(A10,sept!A$111:C$120,3,FALSE) -> 998.161 | D10: =VLOOKUP($A10,sept!$A$96:$C$106,3,FALSE) -> 875.274 | E10: =VLOOKUP($A10,sept!$A$82:$C$92,3,FALSE) -> 1086.553 | F10: =VLOOKUP($A10,sept!$A$68:$C$78,3,FALSE) -> 2223.166 | G10: =VLOOKUP($A10,sept!$A$54:$C$64,3,FALSE) -> 2954.795 | H10: =VLOOKUP($A10,sept!$A$42:$C$50,3,FALSE) -> 2765.645 | I10: =VLOOKUP($A10,sept!$A$28:$C$38,3,FALSE) -> 1321.593 | J10: =VLOOKUP($A10,sept!$A$16:$C$23,3,FALSE) -> 1337.254 | K10: =VLOOKUP($A10,sept!$A$1:$C$9,3,FALSE) -> 859 | L10: =+sept!C133 -> 403.944
A11: Closed | C11: =VLOOKUP(A11,sept!A$111:C$120,3,FALSE) -> 391.894 | D11: =VLOOKUP($A11,sept!$A$96:$C$106,3,FALSE) -> 231.344 | E11: =VLOOKUP($A11,sept!$A$82:$C$92,3,FALSE) -> 311.955 | F11: =VLOOKUP($A11,sept!$A$68:$C$78,3,FALSE) -> 271.277 | G11: =VLOOKUP($A11,sept!$A$54:$C$64,3,FALSE) -> 314.842 | H11: =VLOOKUP($A11,sept!$A$42:$C$50,3,FALSE) -> 223.798 | I11: 0 | L11: 0
A12: Safety | C12: 0 | D12: =VLOOKUP($A12,sept!$A$96:$C$106,3,FALSE) -> 42.86 | E12: =VLOOKUP($A12,sept!$A$82:$C$92,3,FALSE) -> 123.617 | F12: =VLOOKUP($A12,sept!$A$68:$C$78,3,FALSE) -> 64.741 | I12: 0 | L12: 0
A13: Total | C13: =SUM(C4:C12) -> 84717.106 | D13: =SUM(D4:D12) -> 70999.445 | E13: =SUM(E4:E12) -> 69790.446 | F13: =SUM(F4:F12) -> 79137.778 | G13: =SUM(G4:G12) -> 84524.87 | H13: =SUM(H4:H12) -> 98534.119 | I13: =VLOOKUP($A13,sept!$A$28:$C$38,3,FALSE) -> 103010.56 | J13: =SUM(J4:J12) -> 116144.69 | K13: =+sept!C10 -> 104678 | L13: =SUM(L4:L12) -> 93460.433
C17: Jan | D17: Feb | E17: March | F17: April | G17: May | H17: June | I17: July | J17: Aug | K17: Sept | L17: Oct
A18: Electric | B18: Gallons | C18: =+C4 -> 31067.019 | D18: =+D4 -> 33451.662 | E18: =+E4 -> 34936.85 | F18: =+F4 -> 43696.177 | G18: =+G4 -> 51280.472 | H18: =+H4 -> 60046.593 | I18: =+I4 -> 65573.818 | J18: =+J4 -> 69050.33 | ... L18: =+L4 -> 50110.787
A19: No. CaL Gas | B19: Gallons | C19: =+C5+C9 -> 22612.912 | D19: =+D5+D9 -> 13651.538 | E19: =+E5+E9 -> 9999.074 | F19: =+F5+F9 -> 12932.491 | G19: =+G5+G9 -> 13640.617 | H19: =+H5+H9 -> 17332.401 | I19: =+I5+I9 -> 18471.32 | J19: =+J5+J9 -> 27939.118 | ... L19: =+L5+L9 -> 22233.891
A20: So. Cal | B20: Gallons | C20: =+C6+C7 -> 24638.53 | D20: =+D6+D7 -> 18772.475 | E20: =+E6+E7 -> 19168.092 | F20: =+F6+F7 -> 15997.073 | G20: =+G6+G7 -> 12455.936 | H20: =+H6+H7 -> 15160.283 | I20: =+I6+I7 -> 14857.367 | J20: =+J6+J7 -> 15426.936 | ... L20: =+L6+L7 -> 18897.48
A21: Electric Transmission | B21: Gallons | C21: =+C10 -> 998.161 | D21: =+D10 -> 875.274 | E21: =+E10 -> 1086.553 | F21: =+F10 -> 2223.166 | G21: =+G10 -> 2954.795 | H21: =+H10 -> 2765.645 | I21: =+I10 -> 1321.593 | J21: =+J10 -> 1337.254 | ... L21: =+L10 -> 403.944
A22: Fueling | B22: Gallons | C22: =+C8 -> 5008.59 | D22: =+D8 -> 3974.292 | E22: =+E8 -> 4164.305 | F22: =+F8 -> 3952.853 | G22: =+G8 -> 3878.208 | H22: =+H8 -> 3005.399 | I22: =+I8 -> 2786.463 | J22: =+J8 -> 2391.05 | ... L22: =+L8 -> 1814.331
A23: UCCo | B23: Gallons | C23: =+C13 -> 84717.106 | D23: =+D13 -> 70999.445 | E23: =+E13 -> 69790.446 | F23: =+F13 -> 79137.778 | G23: =+G13 -> 84524.87 | H23: =+H13 -> 98534.119 | I23: =+I13 -> 103010.56 | J23: =+J13 -> 116144.69 | ... L23: =+L13 -> 93460.433
C26: Jan | D26: Feb | E26: March | F26: April | G26: May | H26: June | I26: July | J26: Aug | K26: Sept | L26: Oct
A27: Electric | B27: Mh | C27: 27918 | D27: 27168 | E27: 29346 | F27: 33839 | G27: 53734 | H27: 42318 | I27: 73093 | J27: 55389 | K27: 56413 | L27: =43031+28463+716.5 -> 72210.5
A28: No. Ca Gas | B28: Mh | C28: 23871 | D28: 11909 | E28: 8725 | F28: 13302 | G28: 17365 | H28: 11375 | I28: 23579 | J28: 22878 | K28: 22070 | L28: =29524+200 -> 29724
A29: So. Cal | B29: Mh | C29: 7451 | D29: 5620 | E29: 13958 | F29: 12538 | G29: 10832 | H29: 9022 | I29: 15923 | J29: 12648 | K29: 13995 | L29: =18578+1357 -> 19935
A30: Electric Transmission | B30: Mh | C30: 1067 | D30: 394 | E30: 1118 | F30: 2435 | G30: 3881 | H30: 2176 | I30: 3458 | J30: 2343 | K30: 1444 | L30: =1012+320 -> 1332
A31: Fueling | B31: Mh | C31: 7505 | D31: 5922 | E31: 5209 | F31: 3968 | G31: 4383 | H31: 2162 | I31: 4377 | J31: 2818 | K31: 3037 | L31: 3429
A32: UCCo | B32: Mh | C32: =SUM(C27:C31) -> 67812 | D32: =SUM(D27:D31) -> 51013 | E32: =SUM(E27:E31) -> 58356 | F32: =SUM(F27:F31) -> 66082 | G32: =SUM(G27:G31) -> 90195 | H32: =SUM(H27:H31) -> 67053 | I32: =SUM(I27:I31) -> 120430 | J32: =SUM(J27:J31) -> 96076 | ... L32: =SUM(L27:L31) -> 126630.5
C34: Jan | D34: Feb | E34: March | F34: April | G34: May | H34: June | I34: July | J34: Aug | K34: Sept | L34: Oct
A35: Electric | B35: Gallon/MH | C35: =+C18/C27 -> 1.1127953 | D35: =+D18/D27 -> 1.2312891 | E35: =+E18/E27 -> 1.1905149 | F35: =+F18/F27 -> 1.2912963 | G35: =+G18/G27 -> 0.95433938 | H35: =+H18/H27 -> 1.4189374 | I35: =+I18/I27 -> 0.89712856 | J35: =+J18/J27 -> 1.2466434 | ... L35: =+L18/L27 -> 0.6939543
A36: No. Ca Gas | B36: Gallon/MH | C36: =+C19/C28 -> 0.94729638 | D36: =+D19/D28 -> 1.1463211 | E36: =+E19/E28 -> 1.1460257 | F36: =+F19/F28 -> 0.97222155 | G36: =+G19/G28 -> 0.78552358 | H36: =+H19/H28 -> 1.5237276 | I36: =+I19/I28 -> 0.78338013 | J36: =+J19/J28 -> 1.221222 | ... L36: =+L19/L28 -> 0.7480114
A37: So. Cal | B37: Gallon/MH | C37: =+C20/C29 -> 3.3067414 | D37: =+D20/D29 -> 3.340298 | E37: =+E20/E29 -> 1.3732692 | F37: =+F20/F29 -> 1.2758871 | G37: =+G20/G29 -> 1.1499202 | H37: =+H20/H29 -> 1.6803683 | I37: =+I20/I29 -> 0.93307587 | J37: =+J20/J29 -> 1.2197135 | ... L37: =+L20/L29 -> 0.94795485
A38: Electric Transmission | B38: Gallon/MH | C38: =+C21/C30 -> 0.9354836 | D38: =+D21/D30 -> 2.2215076 | E38: =+E21/E30 -> 0.97187209 | F38: =+F21/F30 -> 0.91300452 | G38: =+G21/G30 -> 0.76134888 | H38: =+H21/H30 -> 1.2709766 | I38: =+I21/I30 -> 0.38218421 | J38: =+J21/J30 -> 0.57074434 | ... L38: =+L21/L30 -> 0.30326126
A39: Fueling | B39: Gallon/MH | C39: =+C22/C31 -> 0.66736709 | D39: =+D22/D31 -> 0.67110638 | E39: =+E22/E31 -> 0.79944423 | F39: =+F22/F31 -> 0.99618271 | G39: =+G22/G31 -> 0.88482957 | H39: =+H22/H31 -> 1.3901013 | I39: =+I22/I31 -> 0.6366148 | J39: =+J22/J31 -> 0.84849184 | ... L39: =+L22/L31 -> 0.52911374
A40: UCCo | B40: Gallon/MH | C40: =+C23/C32 -> 1.2492937 | D40: =+D23/D32 -> 1.3917912 | E40: =+E23/E32 -> 1.1959429 | F40: =+F23/F32 -> 1.1975694 | G40: =+G23/G32 -> 0.93713476 | H40: =+H23/H32 -> 1.4694961 | I40: =+I23/I32 -> 0.85535631 | J40: =+J23/J32 -> 1.2088835 | ... L40: =+L23/L32 -> 0.73805626

Sheet sept
A1: Division | B1: Total $ | C1: Gals
A2: Elec | B2: 314121 | C2: 61022
A3: San Diego | B3: 66104.99 | C3: 13026
A4: Gas Tran | B4: =103174+12919 -> 116093 | C4: 20313
A5: Gas Transmission | B5: 0 | C5: 0
A6: So Cal | B6: 23140 | C6: 4357
A7: Gas Dist | B7: 0 | C7: 2472
A8: Fuel | B8: 12835 | C8: 2448
A9: Major Projects | B9: 4044 | C9: 859
A10: Total | B10: =SUM(B2:B9) -> 536337.99 | C10: 104678
A12: Applied filters: Company Number is 1 Year is 2025 Included (1) 09/30/2025 (End of Month)
A15: Division | B15: Total $ | C15: Gals
A16: Elec | B16: 354147.17 | C16: 69050.33
A17: Gas Tran | B17: 67303.01 | C17: 13388.441
A18: Gas Transmission | B18: 60471.58 | C18: 11793.722
A19: San Diego | B19: 39571.78 | C19: 7957.965
A20: So Cal | B20: 37238.63 | C20: 7468.971
A21: Gas Dist | B21: 14527.81 | C21: 2756.955
A22: Fuel | B22: 12323.42 | C22: 2391.05
A23: Major Projects | B23: 6223.53 | C23: 1337.254
A24: Total | B24: 591806.93 | C24: 116144.69
A26: Applied filters: Company Number is 1 Year is 2025 Included (1) 08/31/2025 (End of Month)
A28: Division | B28: Total $ | C28: Gals
A29: Elec | B29: 339618.67 | C29: 65573.818
A30: Gas Tran | B30: 68249.55 | C30: 13534.945
A31: So Cal | B31: 52489.65 | C31: 10918.678
A32: San Diego | B32: 19221.2 | C32: 3938.689
A33: Gas Dist | B33: 17887.13 | C33: 3466.619
A34: Fuel | B34: 14166.76 | C34: 2786.463
A35: Gas Transmission | B35: 7679.59 | C35: 1469.756
A36: Major Projects | B36: 6552.58 | C36: 1321.593
A37: Total | B37: 525865.13 | C37: 103010.56
A39: Applied filters: Company Number is 1 Year is 2025 Included (1) 07/31/2025 (End of Month)
A41: Division | B41: Total $ | C41: Gals
A42: Elec | B42: 314486.32 | C42: 60046.593
A43: Gas Tran | B43: 68903.85 | C43: 13558.782
A44: So Cal | B44: 43698.46 | C44: 9061.299
A45: San Diego | B45: 29343.17 | C45: 6098.984
A46: Gas Dist | B46: 19978.13 | C46: 3773.619
A47: Fuel | B47: 15000.03 | C47: 3005.399
...
